Spawning shell within /home/elsa/Conferences-fairness/Conferences-fairness/.venv

(25, 'Inappropriate ioctl for device')
Updating dependencies
Resolving dependencies...

No dependencies to install or update
Loading of data, time: 10:24:49
Start author data retreival, time: 10:24:50
Traceback (most recent call last):
  File "/opt/itu/easybuild/software/poetry/1.5.1-GCCcore-12.3.0/lib/python3.11/site-packages/requests/models.py", line 971, in json
    return complexjson.loads(self.text, **kwargs)
           ^^^^^^^^^^^^^^^^^^^^^^^^^^^^^^^^^^^^^^
  File "/opt/itu/easybuild/software/Python/3.11.3-GCCcore-12.3.0/lib/python3.11/json/__init__.py", line 346, in loads
    return _default_decoder.decode(s)
           ^^^^^^^^^^^^^^^^^^^^^^^^^^
  File "/opt/itu/easybuild/software/Python/3.11.3-GCCcore-12.3.0/lib/python3.11/json/decoder.py", line 337, in decode
    obj, end = self.raw_decode(s, idx=_w(s, 0).end())
               ^^^^^^^^^^^^^^^^^^^^^^^^^^^^^^^^^^^^^^
  File "/opt/itu/easybuild/software/Python/3.11.3-GCCcore-12.3.0/lib/python3.11/json/decoder.py", line 355, in raw_decode
    raise JSONDecodeError("Expecting value", s, err.value) from None
json.decoder.JSONDecodeError: Expecting value: line 1 column 1 (char 0)

During handling of the above exception, another exception occurred:

Traceback (most recent call last):
  File "/home/elsa/Conferences-fairness/Conferences-fairness/script/get_citation.py", line 158, in <module>
    main()
  File "/home/elsa/Conferences-fairness/Conferences-fairness/script/get_citation.py", line 100, in main
    response_json = requests.get(complete_url).json()
                    ^^^^^^^^^^^^^^^^^^^^^^^^^^^^^^^^^
  File "/opt/itu/easybuild/software/poetry/1.5.1-GCCcore-12.3.0/lib/python3.11/site-packages/requests/models.py", line 975, in json
    raise RequestsJSONDecodeError(e.msg, e.doc, e.pos)
requests.exceptions.JSONDecodeError: Expecting value: line 1 column 1 (char 0)
